{
  "Header": {
    "Original": "CVE-2023-43665 [Denial-of-service possibility in django.utils.text.Truncator]",
    "ID": "CVE-2023-43665",
    "Description": "[Denial-of-service possibility in django.utils.text.Truncator]"
  },
  "Annotations": [
    {
      "Original": "- python-django 3:4.2.6-1 (bug #1053475)",
      "Type": "package",
      "Package": "python-django",
      "Kind": "fixed",
      "Version": "3:4.2.6-1",
      "BugNo": 1053475
    },
    {
      "Original": "NOTE: https://www.openwall.com/lists/oss-security/2023/10/04/6",
      "Type": "NOTE",
      "Description": "https://www.openwall.com/lists/oss-security/2023/10/04/6"
    },
    {
      "Original": "NOTE: https://www.djangoproject.com/weblog/2023/oct/04/security-releases/",
      "Type": "NOTE",
      "Description": "https://www.djangoproject.com/weblog/2023/oct/04/security-releases/"
    },
    {
      "Original": "NOTE: https://github.com/django/django/commit/17b51094d778b421bb2b3aae0c270894b050455d (main)",
      "Type": "NOTE",
      "Description": "https://github.com/django/django/commit/17b51094d778b421bb2b3aae0c270894b050455d (main)"
    },
    {
      "Original": "NOTE: https://github.com/django/django/commit/be9c27c4d18c2e6a5be8af4e53c0797440794473 (4.2.6)",
      "Type": "NOTE",
      "Description": "https://github.com/django/django/commit/be9c27c4d18c2e6a5be8af4e53c0797440794473 (4.2.6)"
    },
    {
      "Original": "NOTE: https://github.com/django/django/commit/ccdade1a0262537868d7ca64374de3d957ca50c5 (3.2.22)",
      "Type": "NOTE",
      "Description": "https://github.com/django/django/commit/ccdade1a0262537868d7ca64374de3d957ca50c5 (3.2.22)"
    }
  ]
}