{
  "Header": {
    "Original": "CVE-2025-57833",
    "ID": "CVE-2025-57833"
  },
  "Annotations": [
    {
      "Original": "- python-django 3:4.2.24-1 (bug #1113865)",
      "Type": "package",
      "Package": "python-django",
      "Kind": "fixed",
      "Version": "3:4.2.24-1",
      "BugNo": 1113865
    },
    {
      "Original": "NOTE: https://www.djangoproject.com/weblog/2025/sep/03/security-releases/",
      "Type": "NOTE",
      "Description": "https://www.djangoproject.com/weblog/2025/sep/03/security-releases/"
    },
    {
      "Original": "NOTE: https://github.com/django/django/commit/31334e6965ad136a5e369993b01721499c5d1a92 (4.2.24)",
      "Type": "NOTE",
      "Description": "https://github.com/django/django/commit/31334e6965ad136a5e369993b01721499c5d1a92 (4.2.24)"
    },
    {
      "Original": "NOTE: https://github.com/django/django/commit/4c044fcc866ec226f612c475950b690b0139d243 (5.2.6)",
      "Type": "NOTE",
      "Description": "https://github.com/django/django/commit/4c044fcc866ec226f612c475950b690b0139d243 (5.2.6)"
    }
  ]
}