{
  "Header": {
    "Original": "CVE-2025-48432 (An issue was discovered in Django 5.2 before 5.2.2, 5.1 before 5.1.10, ...)",
    "ID": "CVE-2025-48432",
    "Description": "(An issue was discovered in Django 5.2 before 5.2.2, 5.1 before 5.1.10, ...)"
  },
  "Annotations": [
    {
      "Original": "- python-django 3:4.2.22-1 (bug #1107282)",
      "Type": "package",
      "Package": "python-django",
      "Kind": "fixed",
      "Version": "3:4.2.22-1",
      "BugNo": 1107282
    },
    {
      "Original": "NOTE: https://www.djangoproject.com/weblog/2025/jun/04/security-releases/",
      "Type": "NOTE",
      "Description": "https://www.djangoproject.com/weblog/2025/jun/04/security-releases/"
    },
    {
      "Original": "NOTE: Fixed by: https://github.com/django/django/commit/ac03c5e7df8680c61cdb0d3bdb8be9095dba841e (4.2.22)",
      "Type": "NOTE",
      "Description": "Fixed by: https://github.com/django/django/commit/ac03c5e7df8680c61cdb0d3bdb8be9095dba841e (4.2.22)"
    }
  ]
}