{
  "Header": {
    "Original": "CVE-2021-33503 (An issue was discovered in urllib3 before 1.26.5. When provided with a ...)",
    "ID": "CVE-2021-33503",
    "Description": "(An issue was discovered in urllib3 before 1.26.5. When provided with a ...)"
  },
  "Annotations": [
    {
      "Original": "- python-urllib3 1.26.5-1~exp1 (bug #989848)",
      "Type": "package",
      "Package": "python-urllib3",
      "Kind": "fixed",
      "Version": "1.26.5-1~exp1",
      "BugNo": 989848
    },
    {
      "Original": "[buster] - python-urllib3 \u003cnot-affected\u003e (Vulnerable code introduced later)",
      "Type": "package",
      "Release": "buster",
      "Package": "python-urllib3",
      "Kind": "not-affected",
      "Description": "Vulnerable code introduced later"
    },
    {
      "Original": "[stretch] - python-urllib3 \u003cnot-affected\u003e (Vulnerable code introduced later)",
      "Type": "package",
      "Release": "stretch",
      "Package": "python-urllib3",
      "Kind": "not-affected",
      "Description": "Vulnerable code introduced later"
    },
    {
      "Original": "NOTE: https://github.com/advisories/GHSA-q2q7-5pp4-w6pg",
      "Type": "NOTE",
      "Description": "https://github.com/advisories/GHSA-q2q7-5pp4-w6pg"
    },
    {
      "Original": "NOTE: https://github.com/urllib3/urllib3/commit/2d4a3fee6de2fa45eb82169361918f759269b4ec",
      "Type": "NOTE",
      "Description": "https://github.com/urllib3/urllib3/commit/2d4a3fee6de2fa45eb82169361918f759269b4ec"
    }
  ]
}